# === 東京タワー (150ブロック) ===

# エリアクリア
fill ~-19 ~0 ~-19 ~19 ~19 ~19 air
fill ~-19 ~20 ~-19 ~19 ~39 ~19 air
fill ~-19 ~40 ~-19 ~19 ~59 ~19 air
fill ~-19 ~60 ~-19 ~19 ~79 ~19 air
fill ~-19 ~80 ~-19 ~19 ~99 ~19 air
fill ~-19 ~100 ~-19 ~19 ~119 ~19 air
fill ~-19 ~120 ~-19 ~19 ~139 ~19 air
fill ~-19 ~140 ~-19 ~19 ~154 ~19 air

# 地面ベース
fill ~-17 ~-1 ~-17 ~17 ~-1 ~17 stone_bricks

# タワー本体
fill ~12 ~0 ~12 ~16 ~0 ~16 orange_concrete
fill ~12 ~0 ~-16 ~16 ~0 ~-12 orange_concrete
fill ~-16 ~0 ~12 ~-12 ~0 ~16 orange_concrete
fill ~-16 ~0 ~-16 ~-12 ~0 ~-12 orange_concrete
fill ~-14 ~0 ~14 ~14 ~0 ~14 orange_concrete
fill ~-14 ~0 ~-14 ~14 ~0 ~-14 orange_concrete
fill ~14 ~0 ~-14 ~14 ~0 ~14 orange_concrete
fill ~-14 ~0 ~-14 ~-14 ~0 ~14 orange_concrete
fill ~13 ~1 ~13 ~15 ~1 ~15 orange_concrete
fill ~13 ~1 ~-15 ~15 ~1 ~-13 orange_concrete
fill ~-15 ~1 ~13 ~-13 ~1 ~15 orange_concrete
fill ~-15 ~1 ~-15 ~-13 ~1 ~-13 orange_concrete
fill ~13 ~2 ~13 ~15 ~2 ~15 orange_concrete
fill ~13 ~2 ~-15 ~15 ~2 ~-13 orange_concrete
fill ~-15 ~2 ~13 ~-13 ~2 ~15 orange_concrete
fill ~-15 ~2 ~-15 ~-13 ~2 ~-13 orange_concrete
fill ~13 ~3 ~13 ~15 ~3 ~15 orange_concrete
fill ~13 ~3 ~-15 ~15 ~3 ~-13 orange_concrete
fill ~-15 ~3 ~13 ~-13 ~3 ~15 orange_concrete
fill ~-15 ~3 ~-15 ~-13 ~3 ~-13 orange_concrete
fill ~13 ~4 ~13 ~15 ~4 ~15 orange_concrete
fill ~13 ~4 ~-15 ~15 ~4 ~-13 orange_concrete
fill ~-15 ~4 ~13 ~-13 ~4 ~15 orange_concrete
fill ~-15 ~4 ~-15 ~-13 ~4 ~-13 orange_concrete
fill ~13 ~5 ~13 ~15 ~5 ~15 orange_concrete
fill ~13 ~5 ~-15 ~15 ~5 ~-13 orange_concrete
fill ~-15 ~5 ~13 ~-13 ~5 ~15 orange_concrete
fill ~-15 ~5 ~-15 ~-13 ~5 ~-13 orange_concrete
fill ~13 ~6 ~13 ~15 ~6 ~15 orange_concrete
fill ~13 ~6 ~-15 ~15 ~6 ~-13 orange_concrete
fill ~-15 ~6 ~13 ~-13 ~6 ~15 orange_concrete
fill ~-15 ~6 ~-15 ~-13 ~6 ~-13 orange_concrete
fill ~12 ~7 ~12 ~14 ~7 ~14 orange_concrete
fill ~12 ~7 ~-14 ~14 ~7 ~-12 orange_concrete
fill ~-14 ~7 ~12 ~-12 ~7 ~14 orange_concrete
fill ~-14 ~7 ~-14 ~-12 ~7 ~-12 orange_concrete
fill ~12 ~8 ~12 ~14 ~8 ~14 orange_concrete
fill ~12 ~8 ~-14 ~14 ~8 ~-12 orange_concrete
fill ~-14 ~8 ~12 ~-12 ~8 ~14 orange_concrete
fill ~-14 ~8 ~-14 ~-12 ~8 ~-12 orange_concrete
fill ~12 ~9 ~12 ~14 ~9 ~14 orange_concrete
fill ~12 ~9 ~-14 ~14 ~9 ~-12 orange_concrete
fill ~-14 ~9 ~12 ~-12 ~9 ~14 orange_concrete
fill ~-14 ~9 ~-14 ~-12 ~9 ~-12 orange_concrete
fill ~12 ~10 ~12 ~14 ~10 ~14 orange_concrete
fill ~12 ~10 ~-14 ~14 ~10 ~-12 orange_concrete
fill ~-14 ~10 ~12 ~-12 ~10 ~14 orange_concrete
fill ~-14 ~10 ~-14 ~-12 ~10 ~-12 orange_concrete
fill ~12 ~11 ~12 ~14 ~11 ~14 orange_concrete
fill ~12 ~11 ~-14 ~14 ~11 ~-12 orange_concrete
fill ~-14 ~11 ~12 ~-12 ~11 ~14 orange_concrete
fill ~-14 ~11 ~-14 ~-12 ~11 ~-12 orange_concrete
fill ~12 ~12 ~12 ~14 ~12 ~14 white_concrete
fill ~12 ~12 ~-14 ~14 ~12 ~-12 white_concrete
fill ~-14 ~12 ~12 ~-12 ~12 ~14 white_concrete
fill ~-14 ~12 ~-14 ~-12 ~12 ~-12 white_concrete
fill ~-13 ~12 ~13 ~13 ~12 ~13 white_concrete
fill ~-13 ~12 ~-13 ~13 ~12 ~-13 white_concrete
fill ~13 ~12 ~-13 ~13 ~12 ~13 white_concrete
fill ~-13 ~12 ~-13 ~-13 ~12 ~13 white_concrete
fill ~12 ~13 ~12 ~14 ~13 ~14 white_concrete
fill ~12 ~13 ~-14 ~14 ~13 ~-12 white_concrete
fill ~-14 ~13 ~12 ~-12 ~13 ~14 white_concrete
fill ~-14 ~13 ~-14 ~-12 ~13 ~-12 white_concrete
fill ~12 ~14 ~12 ~14 ~14 ~14 white_concrete
fill ~12 ~14 ~-14 ~14 ~14 ~-12 white_concrete
fill ~-14 ~14 ~12 ~-12 ~14 ~14 white_concrete
fill ~-14 ~14 ~-14 ~-12 ~14 ~-12 white_concrete
fill ~12 ~15 ~12 ~14 ~15 ~14 white_concrete
fill ~12 ~15 ~-14 ~14 ~15 ~-12 white_concrete
fill ~-14 ~15 ~12 ~-12 ~15 ~14 white_concrete
fill ~-14 ~15 ~-14 ~-12 ~15 ~-12 white_concrete
fill ~12 ~16 ~12 ~14 ~16 ~14 white_concrete
fill ~12 ~16 ~-14 ~14 ~16 ~-12 white_concrete
fill ~-14 ~16 ~12 ~-12 ~16 ~14 white_concrete
fill ~-14 ~16 ~-14 ~-12 ~16 ~-12 white_concrete
fill ~12 ~17 ~12 ~14 ~17 ~14 white_concrete
fill ~12 ~17 ~-14 ~14 ~17 ~-12 white_concrete
fill ~-14 ~17 ~12 ~-12 ~17 ~14 white_concrete
fill ~-14 ~17 ~-14 ~-12 ~17 ~-12 white_concrete
fill ~12 ~18 ~12 ~14 ~18 ~14 white_concrete
fill ~12 ~18 ~-14 ~14 ~18 ~-12 white_concrete
fill ~-14 ~18 ~12 ~-12 ~18 ~14 white_concrete
fill ~-14 ~18 ~-14 ~-12 ~18 ~-12 white_concrete
fill ~11 ~19 ~11 ~13 ~19 ~13 white_concrete
fill ~11 ~19 ~-13 ~13 ~19 ~-11 white_concrete
fill ~-13 ~19 ~11 ~-11 ~19 ~13 white_concrete
fill ~-13 ~19 ~-13 ~-11 ~19 ~-11 white_concrete
fill ~11 ~20 ~11 ~13 ~20 ~13 white_concrete
fill ~11 ~20 ~-13 ~13 ~20 ~-11 white_concrete
fill ~-13 ~20 ~11 ~-11 ~20 ~13 white_concrete
fill ~-13 ~20 ~-13 ~-11 ~20 ~-11 white_concrete
fill ~11 ~21 ~11 ~13 ~21 ~13 white_concrete
fill ~11 ~21 ~-13 ~13 ~21 ~-11 white_concrete
fill ~-13 ~21 ~11 ~-11 ~21 ~13 white_concrete
fill ~-13 ~21 ~-13 ~-11 ~21 ~-11 white_concrete
fill ~11 ~22 ~11 ~13 ~22 ~13 white_concrete
fill ~11 ~22 ~-13 ~13 ~22 ~-11 white_concrete
fill ~-13 ~22 ~11 ~-11 ~22 ~13 white_concrete
fill ~-13 ~22 ~-13 ~-11 ~22 ~-11 white_concrete
fill ~11 ~23 ~11 ~13 ~23 ~13 white_concrete
fill ~11 ~23 ~-13 ~13 ~23 ~-11 white_concrete
fill ~-13 ~23 ~11 ~-11 ~23 ~13 white_concrete
fill ~-13 ~23 ~-13 ~-11 ~23 ~-11 white_concrete
fill ~11 ~24 ~11 ~13 ~24 ~13 orange_concrete
fill ~11 ~24 ~-13 ~13 ~24 ~-11 orange_concrete
fill ~-13 ~24 ~11 ~-11 ~24 ~13 orange_concrete
fill ~-13 ~24 ~-13 ~-11 ~24 ~-11 orange_concrete
fill ~-12 ~24 ~12 ~12 ~24 ~12 orange_concrete
fill ~-12 ~24 ~-12 ~12 ~24 ~-12 orange_concrete
fill ~12 ~24 ~-12 ~12 ~24 ~12 orange_concrete
fill ~-12 ~24 ~-12 ~-12 ~24 ~12 orange_concrete
fill ~11 ~25 ~11 ~13 ~25 ~13 orange_concrete
fill ~11 ~25 ~-13 ~13 ~25 ~-11 orange_concrete
fill ~-13 ~25 ~11 ~-11 ~25 ~13 orange_concrete
fill ~-13 ~25 ~-13 ~-11 ~25 ~-11 orange_concrete
fill ~11 ~26 ~11 ~13 ~26 ~13 orange_concrete
fill ~11 ~26 ~-13 ~13 ~26 ~-11 orange_concrete
fill ~-13 ~26 ~11 ~-11 ~26 ~13 orange_concrete
fill ~-13 ~26 ~-13 ~-11 ~26 ~-11 orange_concrete
fill ~11 ~27 ~11 ~13 ~27 ~13 orange_concrete
fill ~11 ~27 ~-13 ~13 ~27 ~-11 orange_concrete
fill ~-13 ~27 ~11 ~-11 ~27 ~13 orange_concrete
fill ~-13 ~27 ~-13 ~-11 ~27 ~-11 orange_concrete
fill ~11 ~28 ~11 ~13 ~28 ~13 orange_concrete
fill ~11 ~28 ~-13 ~13 ~28 ~-11 orange_concrete
fill ~-13 ~28 ~11 ~-11 ~28 ~13 orange_concrete
fill ~-13 ~28 ~-13 ~-11 ~28 ~-11 orange_concrete
fill ~11 ~29 ~11 ~13 ~29 ~13 orange_concrete
fill ~11 ~29 ~-13 ~13 ~29 ~-11 orange_concrete
fill ~-13 ~29 ~11 ~-11 ~29 ~13 orange_concrete
fill ~-13 ~29 ~-13 ~-11 ~29 ~-11 orange_concrete
fill ~10 ~30 ~10 ~12 ~30 ~12 orange_concrete
fill ~10 ~30 ~-12 ~12 ~30 ~-10 orange_concrete
fill ~-12 ~30 ~10 ~-10 ~30 ~12 orange_concrete
fill ~-12 ~30 ~-12 ~-10 ~30 ~-10 orange_concrete
fill ~10 ~31 ~10 ~12 ~31 ~12 orange_concrete
fill ~10 ~31 ~-12 ~12 ~31 ~-10 orange_concrete
fill ~-12 ~31 ~10 ~-10 ~31 ~12 orange_concrete
fill ~-12 ~31 ~-12 ~-10 ~31 ~-10 orange_concrete
fill ~10 ~32 ~10 ~12 ~32 ~12 orange_concrete
fill ~10 ~32 ~-12 ~12 ~32 ~-10 orange_concrete
fill ~-12 ~32 ~10 ~-10 ~32 ~12 orange_concrete
fill ~-12 ~32 ~-12 ~-10 ~32 ~-10 orange_concrete
fill ~10 ~33 ~10 ~12 ~33 ~12 orange_concrete
fill ~10 ~33 ~-12 ~12 ~33 ~-10 orange_concrete
fill ~-12 ~33 ~10 ~-10 ~33 ~12 orange_concrete
fill ~-12 ~33 ~-12 ~-10 ~33 ~-10 orange_concrete
fill ~10 ~34 ~10 ~12 ~34 ~12 orange_concrete
fill ~10 ~34 ~-12 ~12 ~34 ~-10 orange_concrete
fill ~-12 ~34 ~10 ~-10 ~34 ~12 orange_concrete
fill ~-12 ~34 ~-12 ~-10 ~34 ~-10 orange_concrete
fill ~10 ~35 ~10 ~12 ~35 ~12 orange_concrete
fill ~10 ~35 ~-12 ~12 ~35 ~-10 orange_concrete
fill ~-12 ~35 ~10 ~-10 ~35 ~12 orange_concrete
fill ~-12 ~35 ~-12 ~-10 ~35 ~-10 orange_concrete
fill ~10 ~36 ~10 ~12 ~36 ~12 white_concrete
fill ~10 ~36 ~-12 ~12 ~36 ~-10 white_concrete
fill ~-12 ~36 ~10 ~-10 ~36 ~12 white_concrete
fill ~-12 ~36 ~-12 ~-10 ~36 ~-10 white_concrete
fill ~-11 ~36 ~11 ~11 ~36 ~11 white_concrete
fill ~-11 ~36 ~-11 ~11 ~36 ~-11 white_concrete
fill ~11 ~36 ~-11 ~11 ~36 ~11 white_concrete
fill ~-11 ~36 ~-11 ~-11 ~36 ~11 white_concrete
fill ~10 ~37 ~10 ~12 ~37 ~12 white_concrete
fill ~10 ~37 ~-12 ~12 ~37 ~-10 white_concrete
fill ~-12 ~37 ~10 ~-10 ~37 ~12 white_concrete
fill ~-12 ~37 ~-12 ~-10 ~37 ~-10 white_concrete
fill ~10 ~38 ~10 ~12 ~38 ~12 white_concrete
fill ~10 ~38 ~-12 ~12 ~38 ~-10 white_concrete
fill ~-12 ~38 ~10 ~-10 ~38 ~12 white_concrete
fill ~-12 ~38 ~-12 ~-10 ~38 ~-10 white_concrete
fill ~10 ~39 ~10 ~12 ~39 ~12 white_concrete
fill ~10 ~39 ~-12 ~12 ~39 ~-10 white_concrete
fill ~-12 ~39 ~10 ~-10 ~39 ~12 white_concrete
fill ~-12 ~39 ~-12 ~-10 ~39 ~-10 white_concrete
fill ~10 ~40 ~10 ~12 ~40 ~12 white_concrete
fill ~10 ~40 ~-12 ~12 ~40 ~-10 white_concrete
fill ~-12 ~40 ~10 ~-10 ~40 ~12 white_concrete
fill ~-12 ~40 ~-12 ~-10 ~40 ~-10 white_concrete
fill ~10 ~41 ~10 ~12 ~41 ~12 white_concrete
fill ~10 ~41 ~-12 ~12 ~41 ~-10 white_concrete
fill ~-12 ~41 ~10 ~-10 ~41 ~12 white_concrete
fill ~-12 ~41 ~-12 ~-10 ~41 ~-10 white_concrete
fill ~9 ~42 ~9 ~11 ~42 ~11 white_concrete
fill ~9 ~42 ~-11 ~11 ~42 ~-9 white_concrete
fill ~-11 ~42 ~9 ~-9 ~42 ~11 white_concrete
fill ~-11 ~42 ~-11 ~-9 ~42 ~-9 white_concrete
fill ~9 ~43 ~9 ~11 ~43 ~11 white_concrete
fill ~9 ~43 ~-11 ~11 ~43 ~-9 white_concrete
fill ~-11 ~43 ~9 ~-9 ~43 ~11 white_concrete
fill ~-11 ~43 ~-11 ~-9 ~43 ~-9 white_concrete
fill ~9 ~44 ~9 ~11 ~44 ~11 white_concrete
fill ~9 ~44 ~-11 ~11 ~44 ~-9 white_concrete
fill ~-11 ~44 ~9 ~-9 ~44 ~11 white_concrete
fill ~-11 ~44 ~-11 ~-9 ~44 ~-9 white_concrete
fill ~9 ~45 ~9 ~11 ~45 ~11 white_concrete
fill ~9 ~45 ~-11 ~11 ~45 ~-9 white_concrete
fill ~-11 ~45 ~9 ~-9 ~45 ~11 white_concrete
fill ~-11 ~45 ~-11 ~-9 ~45 ~-9 white_concrete
fill ~9 ~46 ~9 ~11 ~46 ~11 white_concrete
fill ~9 ~46 ~-11 ~11 ~46 ~-9 white_concrete
fill ~-11 ~46 ~9 ~-9 ~46 ~11 white_concrete
fill ~-11 ~46 ~-11 ~-9 ~46 ~-9 white_concrete
fill ~9 ~47 ~9 ~11 ~47 ~11 white_concrete
fill ~9 ~47 ~-11 ~11 ~47 ~-9 white_concrete
fill ~-11 ~47 ~9 ~-9 ~47 ~11 white_concrete
fill ~-11 ~47 ~-11 ~-9 ~47 ~-9 white_concrete
fill ~9 ~48 ~9 ~11 ~48 ~11 orange_concrete
fill ~9 ~48 ~-11 ~11 ~48 ~-9 orange_concrete
fill ~-11 ~48 ~9 ~-9 ~48 ~11 orange_concrete
fill ~-11 ~48 ~-11 ~-9 ~48 ~-9 orange_concrete
fill ~-10 ~48 ~10 ~10 ~48 ~10 orange_concrete
fill ~-10 ~48 ~-10 ~10 ~48 ~-10 orange_concrete
fill ~10 ~48 ~-10 ~10 ~48 ~10 orange_concrete
fill ~-10 ~48 ~-10 ~-10 ~48 ~10 orange_concrete
fill ~9 ~49 ~9 ~11 ~49 ~11 orange_concrete
fill ~9 ~49 ~-11 ~11 ~49 ~-9 orange_concrete
fill ~-11 ~49 ~9 ~-9 ~49 ~11 orange_concrete
fill ~-11 ~49 ~-11 ~-9 ~49 ~-9 orange_concrete
fill ~9 ~50 ~9 ~11 ~50 ~11 orange_concrete
fill ~9 ~50 ~-11 ~11 ~50 ~-9 orange_concrete
fill ~-11 ~50 ~9 ~-9 ~50 ~11 orange_concrete
fill ~-11 ~50 ~-11 ~-9 ~50 ~-9 orange_concrete
fill ~9 ~51 ~9 ~11 ~51 ~11 orange_concrete
fill ~9 ~51 ~-11 ~11 ~51 ~-9 orange_concrete
fill ~-11 ~51 ~9 ~-9 ~51 ~11 orange_concrete
fill ~-11 ~51 ~-11 ~-9 ~51 ~-9 orange_concrete
fill ~9 ~52 ~9 ~11 ~52 ~11 orange_concrete
fill ~9 ~52 ~-11 ~11 ~52 ~-9 orange_concrete
fill ~-11 ~52 ~9 ~-9 ~52 ~11 orange_concrete
fill ~-11 ~52 ~-11 ~-9 ~52 ~-9 orange_concrete
fill ~8 ~53 ~8 ~10 ~53 ~10 orange_concrete
fill ~8 ~53 ~-10 ~10 ~53 ~-8 orange_concrete
fill ~-10 ~53 ~8 ~-8 ~53 ~10 orange_concrete
fill ~-10 ~53 ~-10 ~-8 ~53 ~-8 orange_concrete
fill ~8 ~54 ~8 ~10 ~54 ~10 orange_concrete
fill ~8 ~54 ~-10 ~10 ~54 ~-8 orange_concrete
fill ~-10 ~54 ~8 ~-8 ~54 ~10 orange_concrete
fill ~-10 ~54 ~-10 ~-8 ~54 ~-8 orange_concrete
fill ~8 ~55 ~8 ~10 ~55 ~10 orange_concrete
fill ~8 ~55 ~-10 ~10 ~55 ~-8 orange_concrete
fill ~-10 ~55 ~8 ~-8 ~55 ~10 orange_concrete
fill ~-10 ~55 ~-10 ~-8 ~55 ~-8 orange_concrete
fill ~-13 ~55 ~-13 ~13 ~55 ~13 white_concrete
fill ~8 ~56 ~8 ~10 ~56 ~10 orange_concrete
fill ~8 ~56 ~-10 ~10 ~56 ~-8 orange_concrete
fill ~-10 ~56 ~8 ~-8 ~56 ~10 orange_concrete
fill ~-10 ~56 ~-10 ~-8 ~56 ~-8 orange_concrete
fill ~-13 ~56 ~13 ~13 ~56 ~13 glass
fill ~-13 ~56 ~-13 ~13 ~56 ~-13 glass
fill ~-13 ~56 ~-13 ~-13 ~56 ~13 glass
fill ~13 ~56 ~-13 ~13 ~56 ~13 glass
setblock ~-2 ~56 ~0 sea_lantern
setblock ~2 ~56 ~0 sea_lantern
setblock ~0 ~56 ~-2 sea_lantern
setblock ~0 ~56 ~2 sea_lantern
fill ~8 ~57 ~8 ~10 ~57 ~10 orange_concrete
fill ~8 ~57 ~-10 ~10 ~57 ~-8 orange_concrete
fill ~-10 ~57 ~8 ~-8 ~57 ~10 orange_concrete
fill ~-10 ~57 ~-10 ~-8 ~57 ~-8 orange_concrete
fill ~-13 ~57 ~13 ~13 ~57 ~13 glass
fill ~-13 ~57 ~-13 ~13 ~57 ~-13 glass
fill ~-13 ~57 ~-13 ~-13 ~57 ~13 glass
fill ~13 ~57 ~-13 ~13 ~57 ~13 glass
setblock ~-2 ~57 ~0 sea_lantern
setblock ~2 ~57 ~0 sea_lantern
setblock ~0 ~57 ~-2 sea_lantern
setblock ~0 ~57 ~2 sea_lantern
fill ~8 ~58 ~8 ~10 ~58 ~10 orange_concrete
fill ~8 ~58 ~-10 ~10 ~58 ~-8 orange_concrete
fill ~-10 ~58 ~8 ~-8 ~58 ~10 orange_concrete
fill ~-10 ~58 ~-10 ~-8 ~58 ~-8 orange_concrete
fill ~-13 ~58 ~13 ~13 ~58 ~13 glass
fill ~-13 ~58 ~-13 ~13 ~58 ~-13 glass
fill ~-13 ~58 ~-13 ~-13 ~58 ~13 glass
fill ~13 ~58 ~-13 ~13 ~58 ~13 glass
setblock ~-2 ~58 ~0 sea_lantern
setblock ~2 ~58 ~0 sea_lantern
setblock ~0 ~58 ~-2 sea_lantern
setblock ~0 ~58 ~2 sea_lantern
fill ~8 ~59 ~8 ~10 ~59 ~10 orange_concrete
fill ~8 ~59 ~-10 ~10 ~59 ~-8 orange_concrete
fill ~-10 ~59 ~8 ~-8 ~59 ~10 orange_concrete
fill ~-10 ~59 ~-10 ~-8 ~59 ~-8 orange_concrete
fill ~-13 ~59 ~13 ~13 ~59 ~13 glass
fill ~-13 ~59 ~-13 ~13 ~59 ~-13 glass
fill ~-13 ~59 ~-13 ~-13 ~59 ~13 glass
fill ~13 ~59 ~-13 ~13 ~59 ~13 glass
setblock ~-2 ~59 ~0 sea_lantern
setblock ~2 ~59 ~0 sea_lantern
setblock ~0 ~59 ~-2 sea_lantern
setblock ~0 ~59 ~2 sea_lantern
fill ~8 ~60 ~8 ~10 ~60 ~10 white_concrete
fill ~8 ~60 ~-10 ~10 ~60 ~-8 white_concrete
fill ~-10 ~60 ~8 ~-8 ~60 ~10 white_concrete
fill ~-10 ~60 ~-10 ~-8 ~60 ~-8 white_concrete
fill ~-9 ~60 ~9 ~9 ~60 ~9 white_concrete
fill ~-9 ~60 ~-9 ~9 ~60 ~-9 white_concrete
fill ~9 ~60 ~-9 ~9 ~60 ~9 white_concrete
fill ~-9 ~60 ~-9 ~-9 ~60 ~9 white_concrete
fill ~-13 ~60 ~-13 ~13 ~60 ~13 white_concrete
fill ~8 ~61 ~8 ~10 ~61 ~10 white_concrete
fill ~8 ~61 ~-10 ~10 ~61 ~-8 white_concrete
fill ~-10 ~61 ~8 ~-8 ~61 ~10 white_concrete
fill ~-10 ~61 ~-10 ~-8 ~61 ~-8 white_concrete
fill ~8 ~62 ~8 ~10 ~62 ~10 white_concrete
fill ~8 ~62 ~-10 ~10 ~62 ~-8 white_concrete
fill ~-10 ~62 ~8 ~-8 ~62 ~10 white_concrete
fill ~-10 ~62 ~-10 ~-8 ~62 ~-8 white_concrete
fill ~8 ~63 ~8 ~10 ~63 ~10 white_concrete
fill ~8 ~63 ~-10 ~10 ~63 ~-8 white_concrete
fill ~-10 ~63 ~8 ~-8 ~63 ~10 white_concrete
fill ~-10 ~63 ~-10 ~-8 ~63 ~-8 white_concrete
fill ~7 ~64 ~7 ~9 ~64 ~9 white_concrete
fill ~7 ~64 ~-9 ~9 ~64 ~-7 white_concrete
fill ~-9 ~64 ~7 ~-7 ~64 ~9 white_concrete
fill ~-9 ~64 ~-9 ~-7 ~64 ~-7 white_concrete
fill ~7 ~65 ~7 ~9 ~65 ~9 white_concrete
fill ~7 ~65 ~-9 ~9 ~65 ~-7 white_concrete
fill ~-9 ~65 ~7 ~-7 ~65 ~9 white_concrete
fill ~-9 ~65 ~-9 ~-7 ~65 ~-7 white_concrete
fill ~7 ~66 ~7 ~9 ~66 ~9 white_concrete
fill ~7 ~66 ~-9 ~9 ~66 ~-7 white_concrete
fill ~-9 ~66 ~7 ~-7 ~66 ~9 white_concrete
fill ~-9 ~66 ~-9 ~-7 ~66 ~-7 white_concrete
fill ~7 ~67 ~7 ~9 ~67 ~9 white_concrete
fill ~7 ~67 ~-9 ~9 ~67 ~-7 white_concrete
fill ~-9 ~67 ~7 ~-7 ~67 ~9 white_concrete
fill ~-9 ~67 ~-9 ~-7 ~67 ~-7 white_concrete
fill ~7 ~68 ~7 ~9 ~68 ~9 white_concrete
fill ~7 ~68 ~-9 ~9 ~68 ~-7 white_concrete
fill ~-9 ~68 ~7 ~-7 ~68 ~9 white_concrete
fill ~-9 ~68 ~-9 ~-7 ~68 ~-7 white_concrete
fill ~7 ~69 ~7 ~9 ~69 ~9 white_concrete
fill ~7 ~69 ~-9 ~9 ~69 ~-7 white_concrete
fill ~-9 ~69 ~7 ~-7 ~69 ~9 white_concrete
fill ~-9 ~69 ~-9 ~-7 ~69 ~-7 white_concrete
fill ~7 ~70 ~7 ~9 ~70 ~9 white_concrete
fill ~7 ~70 ~-9 ~9 ~70 ~-7 white_concrete
fill ~-9 ~70 ~7 ~-7 ~70 ~9 white_concrete
fill ~-9 ~70 ~-9 ~-7 ~70 ~-7 white_concrete
fill ~7 ~71 ~7 ~9 ~71 ~9 white_concrete
fill ~7 ~71 ~-9 ~9 ~71 ~-7 white_concrete
fill ~-9 ~71 ~7 ~-7 ~71 ~9 white_concrete
fill ~-9 ~71 ~-9 ~-7 ~71 ~-7 white_concrete
fill ~7 ~72 ~7 ~9 ~72 ~9 orange_concrete
fill ~7 ~72 ~-9 ~9 ~72 ~-7 orange_concrete
fill ~-9 ~72 ~7 ~-7 ~72 ~9 orange_concrete
fill ~-9 ~72 ~-9 ~-7 ~72 ~-7 orange_concrete
fill ~-8 ~72 ~8 ~8 ~72 ~8 orange_concrete
fill ~-8 ~72 ~-8 ~8 ~72 ~-8 orange_concrete
fill ~8 ~72 ~-8 ~8 ~72 ~8 orange_concrete
fill ~-8 ~72 ~-8 ~-8 ~72 ~8 orange_concrete
fill ~7 ~73 ~7 ~9 ~73 ~9 orange_concrete
fill ~7 ~73 ~-9 ~9 ~73 ~-7 orange_concrete
fill ~-9 ~73 ~7 ~-7 ~73 ~9 orange_concrete
fill ~-9 ~73 ~-9 ~-7 ~73 ~-7 orange_concrete
fill ~6 ~74 ~6 ~8 ~74 ~8 orange_concrete
fill ~6 ~74 ~-8 ~8 ~74 ~-6 orange_concrete
fill ~-8 ~74 ~6 ~-6 ~74 ~8 orange_concrete
fill ~-8 ~74 ~-8 ~-6 ~74 ~-6 orange_concrete
fill ~6 ~75 ~6 ~8 ~75 ~8 orange_concrete
fill ~6 ~75 ~-8 ~8 ~75 ~-6 orange_concrete
fill ~-8 ~75 ~6 ~-6 ~75 ~8 orange_concrete
fill ~-8 ~75 ~-8 ~-6 ~75 ~-6 orange_concrete
fill ~6 ~76 ~6 ~8 ~76 ~8 orange_concrete
fill ~6 ~76 ~-8 ~8 ~76 ~-6 orange_concrete
fill ~-8 ~76 ~6 ~-6 ~76 ~8 orange_concrete
fill ~-8 ~76 ~-8 ~-6 ~76 ~-6 orange_concrete
fill ~6 ~77 ~6 ~8 ~77 ~8 orange_concrete
fill ~6 ~77 ~-8 ~8 ~77 ~-6 orange_concrete
fill ~-8 ~77 ~6 ~-6 ~77 ~8 orange_concrete
fill ~-8 ~77 ~-8 ~-6 ~77 ~-6 orange_concrete
fill ~6 ~78 ~6 ~8 ~78 ~8 orange_concrete
fill ~6 ~78 ~-8 ~8 ~78 ~-6 orange_concrete
fill ~-8 ~78 ~6 ~-6 ~78 ~8 orange_concrete
fill ~-8 ~78 ~-8 ~-6 ~78 ~-6 orange_concrete
setblock ~7 ~79 ~7 orange_concrete
setblock ~7 ~79 ~-7 orange_concrete
setblock ~-7 ~79 ~7 orange_concrete
setblock ~-7 ~79 ~-7 orange_concrete
setblock ~7 ~80 ~7 orange_concrete
setblock ~7 ~80 ~-7 orange_concrete
setblock ~-7 ~80 ~7 orange_concrete
setblock ~-7 ~80 ~-7 orange_concrete
setblock ~7 ~81 ~7 orange_concrete
setblock ~7 ~81 ~-7 orange_concrete
setblock ~-7 ~81 ~7 orange_concrete
setblock ~-7 ~81 ~-7 orange_concrete
setblock ~7 ~82 ~7 orange_concrete
setblock ~7 ~82 ~-7 orange_concrete
setblock ~-7 ~82 ~7 orange_concrete
setblock ~-7 ~82 ~-7 orange_concrete
setblock ~7 ~83 ~7 orange_concrete
setblock ~7 ~83 ~-7 orange_concrete
setblock ~-7 ~83 ~7 orange_concrete
setblock ~-7 ~83 ~-7 orange_concrete
setblock ~6 ~84 ~6 white_concrete
setblock ~6 ~84 ~-6 white_concrete
setblock ~-6 ~84 ~6 white_concrete
setblock ~-6 ~84 ~-6 white_concrete
fill ~-6 ~84 ~6 ~6 ~84 ~6 white_concrete
fill ~-6 ~84 ~-6 ~6 ~84 ~-6 white_concrete
fill ~6 ~84 ~-6 ~6 ~84 ~6 white_concrete
fill ~-6 ~84 ~-6 ~-6 ~84 ~6 white_concrete
setblock ~6 ~85 ~6 white_concrete
setblock ~6 ~85 ~-6 white_concrete
setblock ~-6 ~85 ~6 white_concrete
setblock ~-6 ~85 ~-6 white_concrete
setblock ~6 ~86 ~6 white_concrete
setblock ~6 ~86 ~-6 white_concrete
setblock ~-6 ~86 ~6 white_concrete
setblock ~-6 ~86 ~-6 white_concrete
setblock ~6 ~87 ~6 white_concrete
setblock ~6 ~87 ~-6 white_concrete
setblock ~-6 ~87 ~6 white_concrete
setblock ~-6 ~87 ~-6 white_concrete
setblock ~6 ~88 ~6 white_concrete
setblock ~6 ~88 ~-6 white_concrete
setblock ~-6 ~88 ~6 white_concrete
setblock ~-6 ~88 ~-6 white_concrete
setblock ~6 ~89 ~6 white_concrete
setblock ~6 ~89 ~-6 white_concrete
setblock ~-6 ~89 ~6 white_concrete
setblock ~-6 ~89 ~-6 white_concrete
setblock ~6 ~90 ~6 white_concrete
setblock ~6 ~90 ~-6 white_concrete
setblock ~-6 ~90 ~6 white_concrete
setblock ~-6 ~90 ~-6 white_concrete
setblock ~6 ~91 ~6 white_concrete
setblock ~6 ~91 ~-6 white_concrete
setblock ~-6 ~91 ~6 white_concrete
setblock ~-6 ~91 ~-6 white_concrete
setblock ~6 ~92 ~6 white_concrete
setblock ~6 ~92 ~-6 white_concrete
setblock ~-6 ~92 ~6 white_concrete
setblock ~-6 ~92 ~-6 white_concrete
setblock ~5 ~93 ~5 white_concrete
setblock ~5 ~93 ~-5 white_concrete
setblock ~-5 ~93 ~5 white_concrete
setblock ~-5 ~93 ~-5 white_concrete
setblock ~5 ~94 ~5 white_concrete
setblock ~5 ~94 ~-5 white_concrete
setblock ~-5 ~94 ~5 white_concrete
setblock ~-5 ~94 ~-5 white_concrete
setblock ~5 ~95 ~5 white_concrete
setblock ~5 ~95 ~-5 white_concrete
setblock ~-5 ~95 ~5 white_concrete
setblock ~-5 ~95 ~-5 white_concrete
fill ~-7 ~95 ~-7 ~7 ~95 ~7 white_concrete
setblock ~5 ~96 ~5 orange_concrete
setblock ~5 ~96 ~-5 orange_concrete
setblock ~-5 ~96 ~5 orange_concrete
setblock ~-5 ~96 ~-5 orange_concrete
fill ~-5 ~96 ~5 ~5 ~96 ~5 orange_concrete
fill ~-5 ~96 ~-5 ~5 ~96 ~-5 orange_concrete
fill ~5 ~96 ~-5 ~5 ~96 ~5 orange_concrete
fill ~-5 ~96 ~-5 ~-5 ~96 ~5 orange_concrete
fill ~-7 ~96 ~7 ~7 ~96 ~7 glass
fill ~-7 ~96 ~-7 ~7 ~96 ~-7 glass
fill ~-7 ~96 ~-7 ~-7 ~96 ~7 glass
fill ~7 ~96 ~-7 ~7 ~96 ~7 glass
setblock ~0 ~96 ~0 sea_lantern
setblock ~5 ~97 ~5 orange_concrete
setblock ~5 ~97 ~-5 orange_concrete
setblock ~-5 ~97 ~5 orange_concrete
setblock ~-5 ~97 ~-5 orange_concrete
fill ~-7 ~97 ~7 ~7 ~97 ~7 glass
fill ~-7 ~97 ~-7 ~7 ~97 ~-7 glass
fill ~-7 ~97 ~-7 ~-7 ~97 ~7 glass
fill ~7 ~97 ~-7 ~7 ~97 ~7 glass
setblock ~0 ~97 ~0 sea_lantern
setblock ~5 ~98 ~5 orange_concrete
setblock ~5 ~98 ~-5 orange_concrete
setblock ~-5 ~98 ~5 orange_concrete
setblock ~-5 ~98 ~-5 orange_concrete
fill ~-7 ~98 ~7 ~7 ~98 ~7 glass
fill ~-7 ~98 ~-7 ~7 ~98 ~-7 glass
fill ~-7 ~98 ~-7 ~-7 ~98 ~7 glass
fill ~7 ~98 ~-7 ~7 ~98 ~7 glass
setblock ~0 ~98 ~0 sea_lantern
setblock ~5 ~99 ~5 orange_concrete
setblock ~5 ~99 ~-5 orange_concrete
setblock ~-5 ~99 ~5 orange_concrete
setblock ~-5 ~99 ~-5 orange_concrete
fill ~-7 ~99 ~-7 ~7 ~99 ~7 white_concrete
setblock ~5 ~100 ~5 orange_concrete
setblock ~5 ~100 ~-5 orange_concrete
setblock ~-5 ~100 ~5 orange_concrete
setblock ~-5 ~100 ~-5 orange_concrete
setblock ~5 ~101 ~5 orange_concrete
setblock ~5 ~101 ~-5 orange_concrete
setblock ~-5 ~101 ~5 orange_concrete
setblock ~-5 ~101 ~-5 orange_concrete
setblock ~4 ~102 ~4 orange_concrete
setblock ~4 ~102 ~-4 orange_concrete
setblock ~-4 ~102 ~4 orange_concrete
setblock ~-4 ~102 ~-4 orange_concrete
setblock ~4 ~103 ~4 orange_concrete
setblock ~4 ~103 ~-4 orange_concrete
setblock ~-4 ~103 ~4 orange_concrete
setblock ~-4 ~103 ~-4 orange_concrete
setblock ~4 ~104 ~4 orange_concrete
setblock ~4 ~104 ~-4 orange_concrete
setblock ~-4 ~104 ~4 orange_concrete
setblock ~-4 ~104 ~-4 orange_concrete
setblock ~4 ~105 ~4 orange_concrete
setblock ~4 ~105 ~-4 orange_concrete
setblock ~-4 ~105 ~4 orange_concrete
setblock ~-4 ~105 ~-4 orange_concrete
setblock ~4 ~106 ~4 orange_concrete
setblock ~4 ~106 ~-4 orange_concrete
setblock ~-4 ~106 ~4 orange_concrete
setblock ~-4 ~106 ~-4 orange_concrete
setblock ~4 ~107 ~4 orange_concrete
setblock ~4 ~107 ~-4 orange_concrete
setblock ~-4 ~107 ~4 orange_concrete
setblock ~-4 ~107 ~-4 orange_concrete
setblock ~4 ~108 ~4 white_concrete
setblock ~4 ~108 ~-4 white_concrete
setblock ~-4 ~108 ~4 white_concrete
setblock ~-4 ~108 ~-4 white_concrete
fill ~-4 ~108 ~4 ~4 ~108 ~4 white_concrete
fill ~-4 ~108 ~-4 ~4 ~108 ~-4 white_concrete
fill ~4 ~108 ~-4 ~4 ~108 ~4 white_concrete
fill ~-4 ~108 ~-4 ~-4 ~108 ~4 white_concrete
setblock ~4 ~109 ~4 white_concrete
setblock ~4 ~109 ~-4 white_concrete
setblock ~-4 ~109 ~4 white_concrete
setblock ~-4 ~109 ~-4 white_concrete
fill ~-3 ~110 ~3 ~3 ~110 ~3 white_concrete
fill ~-3 ~110 ~-3 ~3 ~110 ~-3 white_concrete
fill ~3 ~110 ~-3 ~3 ~110 ~3 white_concrete
fill ~-3 ~110 ~-3 ~-3 ~110 ~3 white_concrete
fill ~-3 ~111 ~3 ~3 ~111 ~3 white_concrete
fill ~-3 ~111 ~-3 ~3 ~111 ~-3 white_concrete
fill ~3 ~111 ~-3 ~3 ~111 ~3 white_concrete
fill ~-3 ~111 ~-3 ~-3 ~111 ~3 white_concrete
fill ~-3 ~112 ~3 ~3 ~112 ~3 white_concrete
fill ~-3 ~112 ~-3 ~3 ~112 ~-3 white_concrete
fill ~3 ~112 ~-3 ~3 ~112 ~3 white_concrete
fill ~-3 ~112 ~-3 ~-3 ~112 ~3 white_concrete
fill ~-3 ~113 ~3 ~3 ~113 ~3 white_concrete
fill ~-3 ~113 ~-3 ~3 ~113 ~-3 white_concrete
fill ~3 ~113 ~-3 ~3 ~113 ~3 white_concrete
fill ~-3 ~113 ~-3 ~-3 ~113 ~3 white_concrete
fill ~-3 ~114 ~3 ~3 ~114 ~3 white_concrete
fill ~-3 ~114 ~-3 ~3 ~114 ~-3 white_concrete
fill ~3 ~114 ~-3 ~3 ~114 ~3 white_concrete
fill ~-3 ~114 ~-3 ~-3 ~114 ~3 white_concrete
fill ~-3 ~115 ~3 ~3 ~115 ~3 white_concrete
fill ~-3 ~115 ~-3 ~3 ~115 ~-3 white_concrete
fill ~3 ~115 ~-3 ~3 ~115 ~3 white_concrete
fill ~-3 ~115 ~-3 ~-3 ~115 ~3 white_concrete
fill ~-3 ~116 ~3 ~3 ~116 ~3 white_concrete
fill ~-3 ~116 ~-3 ~3 ~116 ~-3 white_concrete
fill ~3 ~116 ~-3 ~3 ~116 ~3 white_concrete
fill ~-3 ~116 ~-3 ~-3 ~116 ~3 white_concrete
fill ~-2 ~117 ~2 ~2 ~117 ~2 white_concrete
fill ~-2 ~117 ~-2 ~2 ~117 ~-2 white_concrete
fill ~2 ~117 ~-2 ~2 ~117 ~2 white_concrete
fill ~-2 ~117 ~-2 ~-2 ~117 ~2 white_concrete
fill ~-2 ~118 ~2 ~2 ~118 ~2 white_concrete
fill ~-2 ~118 ~-2 ~2 ~118 ~-2 white_concrete
fill ~2 ~118 ~-2 ~2 ~118 ~2 white_concrete
fill ~-2 ~118 ~-2 ~-2 ~118 ~2 white_concrete
fill ~-2 ~119 ~2 ~2 ~119 ~2 white_concrete
fill ~-2 ~119 ~-2 ~2 ~119 ~-2 white_concrete
fill ~2 ~119 ~-2 ~2 ~119 ~2 white_concrete
fill ~-2 ~119 ~-2 ~-2 ~119 ~2 white_concrete
fill ~-2 ~120 ~2 ~2 ~120 ~2 orange_concrete
fill ~-2 ~120 ~-2 ~2 ~120 ~-2 orange_concrete
fill ~2 ~120 ~-2 ~2 ~120 ~2 orange_concrete
fill ~-2 ~120 ~-2 ~-2 ~120 ~2 orange_concrete
fill ~-2 ~121 ~2 ~2 ~121 ~2 orange_concrete
fill ~-2 ~121 ~-2 ~2 ~121 ~-2 orange_concrete
fill ~2 ~121 ~-2 ~2 ~121 ~2 orange_concrete
fill ~-2 ~121 ~-2 ~-2 ~121 ~2 orange_concrete
fill ~-2 ~122 ~2 ~2 ~122 ~2 orange_concrete
fill ~-2 ~122 ~-2 ~2 ~122 ~-2 orange_concrete
fill ~2 ~122 ~-2 ~2 ~122 ~2 orange_concrete
fill ~-2 ~122 ~-2 ~-2 ~122 ~2 orange_concrete
fill ~-2 ~123 ~2 ~2 ~123 ~2 orange_concrete
fill ~-2 ~123 ~-2 ~2 ~123 ~-2 orange_concrete
fill ~2 ~123 ~-2 ~2 ~123 ~2 orange_concrete
fill ~-2 ~123 ~-2 ~-2 ~123 ~2 orange_concrete
setblock ~0 ~124 ~0 orange_concrete
setblock ~0 ~125 ~0 orange_concrete
setblock ~0 ~126 ~0 orange_concrete
setblock ~0 ~127 ~0 orange_concrete
setblock ~0 ~128 ~0 orange_concrete
setblock ~0 ~129 ~0 orange_concrete

# 斜め補強材
setblock ~-12 ~1 ~14 orange_concrete
setblock ~12 ~1 ~14 orange_concrete
setblock ~-12 ~1 ~-14 orange_concrete
setblock ~12 ~1 ~-14 orange_concrete
setblock ~14 ~1 ~-12 orange_concrete
setblock ~14 ~1 ~12 orange_concrete
setblock ~-14 ~1 ~-12 orange_concrete
setblock ~-14 ~1 ~12 orange_concrete
setblock ~-9 ~2 ~14 orange_concrete
setblock ~9 ~2 ~14 orange_concrete
setblock ~-9 ~2 ~-14 orange_concrete
setblock ~9 ~2 ~-14 orange_concrete
setblock ~14 ~2 ~-9 orange_concrete
setblock ~14 ~2 ~9 orange_concrete
setblock ~-14 ~2 ~-9 orange_concrete
setblock ~-14 ~2 ~9 orange_concrete
setblock ~-7 ~3 ~14 orange_concrete
setblock ~7 ~3 ~14 orange_concrete
setblock ~-7 ~3 ~-14 orange_concrete
setblock ~7 ~3 ~-14 orange_concrete
setblock ~14 ~3 ~-7 orange_concrete
setblock ~14 ~3 ~7 orange_concrete
setblock ~-14 ~3 ~-7 orange_concrete
setblock ~-14 ~3 ~7 orange_concrete
setblock ~-5 ~4 ~14 orange_concrete
setblock ~5 ~4 ~14 orange_concrete
setblock ~-5 ~4 ~-14 orange_concrete
setblock ~5 ~4 ~-14 orange_concrete
setblock ~14 ~4 ~-5 orange_concrete
setblock ~14 ~4 ~5 orange_concrete
setblock ~-14 ~4 ~-5 orange_concrete
setblock ~-14 ~4 ~5 orange_concrete
setblock ~-3 ~5 ~14 orange_concrete
setblock ~3 ~5 ~14 orange_concrete
setblock ~-3 ~5 ~-14 orange_concrete
setblock ~3 ~5 ~-14 orange_concrete
setblock ~14 ~5 ~-3 orange_concrete
setblock ~14 ~5 ~3 orange_concrete
setblock ~-14 ~5 ~-3 orange_concrete
setblock ~-14 ~5 ~3 orange_concrete
setblock ~0 ~6 ~14 orange_concrete
setblock ~0 ~6 ~14 orange_concrete
setblock ~0 ~6 ~-14 orange_concrete
setblock ~0 ~6 ~-14 orange_concrete
setblock ~14 ~6 ~0 orange_concrete
setblock ~14 ~6 ~0 orange_concrete
setblock ~-14 ~6 ~0 orange_concrete
setblock ~-14 ~6 ~0 orange_concrete
setblock ~2 ~7 ~13 orange_concrete
setblock ~-2 ~7 ~13 orange_concrete
setblock ~2 ~7 ~-13 orange_concrete
setblock ~-2 ~7 ~-13 orange_concrete
setblock ~13 ~7 ~2 orange_concrete
setblock ~13 ~7 ~-2 orange_concrete
setblock ~-13 ~7 ~2 orange_concrete
setblock ~-13 ~7 ~-2 orange_concrete
setblock ~4 ~8 ~13 orange_concrete
setblock ~-4 ~8 ~13 orange_concrete
setblock ~4 ~8 ~-13 orange_concrete
setblock ~-4 ~8 ~-13 orange_concrete
setblock ~13 ~8 ~4 orange_concrete
setblock ~13 ~8 ~-4 orange_concrete
setblock ~-13 ~8 ~4 orange_concrete
setblock ~-13 ~8 ~-4 orange_concrete
setblock ~6 ~9 ~13 orange_concrete
setblock ~-6 ~9 ~13 orange_concrete
setblock ~6 ~9 ~-13 orange_concrete
setblock ~-6 ~9 ~-13 orange_concrete
setblock ~13 ~9 ~6 orange_concrete
setblock ~13 ~9 ~-6 orange_concrete
setblock ~-13 ~9 ~6 orange_concrete
setblock ~-13 ~9 ~-6 orange_concrete
setblock ~9 ~10 ~13 orange_concrete
setblock ~-9 ~10 ~13 orange_concrete
setblock ~9 ~10 ~-13 orange_concrete
setblock ~-9 ~10 ~-13 orange_concrete
setblock ~13 ~10 ~9 orange_concrete
setblock ~13 ~10 ~-9 orange_concrete
setblock ~-13 ~10 ~9 orange_concrete
setblock ~-13 ~10 ~-9 orange_concrete
setblock ~11 ~11 ~13 orange_concrete
setblock ~-11 ~11 ~13 orange_concrete
setblock ~11 ~11 ~-13 orange_concrete
setblock ~-11 ~11 ~-13 orange_concrete
setblock ~13 ~11 ~11 orange_concrete
setblock ~13 ~11 ~-11 orange_concrete
setblock ~-13 ~11 ~11 orange_concrete
setblock ~-13 ~11 ~-11 orange_concrete
setblock ~-11 ~13 ~13 white_concrete
setblock ~11 ~13 ~13 white_concrete
setblock ~-11 ~13 ~-13 white_concrete
setblock ~11 ~13 ~-13 white_concrete
setblock ~13 ~13 ~-11 white_concrete
setblock ~13 ~13 ~11 white_concrete
setblock ~-13 ~13 ~-11 white_concrete
setblock ~-13 ~13 ~11 white_concrete
setblock ~-9 ~14 ~13 white_concrete
setblock ~9 ~14 ~13 white_concrete
setblock ~-9 ~14 ~-13 white_concrete
setblock ~9 ~14 ~-13 white_concrete
setblock ~13 ~14 ~-9 white_concrete
setblock ~13 ~14 ~9 white_concrete
setblock ~-13 ~14 ~-9 white_concrete
setblock ~-13 ~14 ~9 white_concrete
setblock ~-7 ~15 ~13 white_concrete
setblock ~7 ~15 ~13 white_concrete
setblock ~-7 ~15 ~-13 white_concrete
setblock ~7 ~15 ~-13 white_concrete
setblock ~13 ~15 ~-7 white_concrete
setblock ~13 ~15 ~7 white_concrete
setblock ~-13 ~15 ~-7 white_concrete
setblock ~-13 ~15 ~7 white_concrete
setblock ~-5 ~16 ~13 white_concrete
setblock ~5 ~16 ~13 white_concrete
setblock ~-5 ~16 ~-13 white_concrete
setblock ~5 ~16 ~-13 white_concrete
setblock ~13 ~16 ~-5 white_concrete
setblock ~13 ~16 ~5 white_concrete
setblock ~-13 ~16 ~-5 white_concrete
setblock ~-13 ~16 ~5 white_concrete
setblock ~-3 ~17 ~13 white_concrete
setblock ~3 ~17 ~13 white_concrete
setblock ~-3 ~17 ~-13 white_concrete
setblock ~3 ~17 ~-13 white_concrete
setblock ~13 ~17 ~-3 white_concrete
setblock ~13 ~17 ~3 white_concrete
setblock ~-13 ~17 ~-3 white_concrete
setblock ~-13 ~17 ~3 white_concrete
setblock ~-1 ~18 ~13 white_concrete
setblock ~1 ~18 ~13 white_concrete
setblock ~-1 ~18 ~-13 white_concrete
setblock ~1 ~18 ~-13 white_concrete
setblock ~13 ~18 ~-1 white_concrete
setblock ~13 ~18 ~1 white_concrete
setblock ~-13 ~18 ~-1 white_concrete
setblock ~-13 ~18 ~1 white_concrete
setblock ~2 ~19 ~12 white_concrete
setblock ~-2 ~19 ~12 white_concrete
setblock ~2 ~19 ~-12 white_concrete
setblock ~-2 ~19 ~-12 white_concrete
setblock ~12 ~19 ~2 white_concrete
setblock ~12 ~19 ~-2 white_concrete
setblock ~-12 ~19 ~2 white_concrete
setblock ~-12 ~19 ~-2 white_concrete
setblock ~4 ~20 ~12 white_concrete
setblock ~-4 ~20 ~12 white_concrete
setblock ~4 ~20 ~-12 white_concrete
setblock ~-4 ~20 ~-12 white_concrete
setblock ~12 ~20 ~4 white_concrete
setblock ~12 ~20 ~-4 white_concrete
setblock ~-12 ~20 ~4 white_concrete
setblock ~-12 ~20 ~-4 white_concrete
setblock ~6 ~21 ~12 white_concrete
setblock ~-6 ~21 ~12 white_concrete
setblock ~6 ~21 ~-12 white_concrete
setblock ~-6 ~21 ~-12 white_concrete
setblock ~12 ~21 ~6 white_concrete
setblock ~12 ~21 ~-6 white_concrete
setblock ~-12 ~21 ~6 white_concrete
setblock ~-12 ~21 ~-6 white_concrete
setblock ~8 ~22 ~12 white_concrete
setblock ~-8 ~22 ~12 white_concrete
setblock ~8 ~22 ~-12 white_concrete
setblock ~-8 ~22 ~-12 white_concrete
setblock ~12 ~22 ~8 white_concrete
setblock ~12 ~22 ~-8 white_concrete
setblock ~-12 ~22 ~8 white_concrete
setblock ~-12 ~22 ~-8 white_concrete
setblock ~10 ~23 ~12 white_concrete
setblock ~-10 ~23 ~12 white_concrete
setblock ~10 ~23 ~-12 white_concrete
setblock ~-10 ~23 ~-12 white_concrete
setblock ~12 ~23 ~10 white_concrete
setblock ~12 ~23 ~-10 white_concrete
setblock ~-12 ~23 ~10 white_concrete
setblock ~-12 ~23 ~-10 white_concrete
setblock ~-10 ~25 ~12 orange_concrete
setblock ~10 ~25 ~12 orange_concrete
setblock ~-10 ~25 ~-12 orange_concrete
setblock ~10 ~25 ~-12 orange_concrete
setblock ~12 ~25 ~-10 orange_concrete
setblock ~12 ~25 ~10 orange_concrete
setblock ~-12 ~25 ~-10 orange_concrete
setblock ~-12 ~25 ~10 orange_concrete
setblock ~-8 ~26 ~12 orange_concrete
setblock ~8 ~26 ~12 orange_concrete
setblock ~-8 ~26 ~-12 orange_concrete
setblock ~8 ~26 ~-12 orange_concrete
setblock ~12 ~26 ~-8 orange_concrete
setblock ~12 ~26 ~8 orange_concrete
setblock ~-12 ~26 ~-8 orange_concrete
setblock ~-12 ~26 ~8 orange_concrete
setblock ~-6 ~27 ~12 orange_concrete
setblock ~6 ~27 ~12 orange_concrete
setblock ~-6 ~27 ~-12 orange_concrete
setblock ~6 ~27 ~-12 orange_concrete
setblock ~12 ~27 ~-6 orange_concrete
setblock ~12 ~27 ~6 orange_concrete
setblock ~-12 ~27 ~-6 orange_concrete
setblock ~-12 ~27 ~6 orange_concrete
setblock ~-4 ~28 ~12 orange_concrete
setblock ~4 ~28 ~12 orange_concrete
setblock ~-4 ~28 ~-12 orange_concrete
setblock ~4 ~28 ~-12 orange_concrete
setblock ~12 ~28 ~-4 orange_concrete
setblock ~12 ~28 ~4 orange_concrete
setblock ~-12 ~28 ~-4 orange_concrete
setblock ~-12 ~28 ~4 orange_concrete
setblock ~-2 ~29 ~12 orange_concrete
setblock ~2 ~29 ~12 orange_concrete
setblock ~-2 ~29 ~-12 orange_concrete
setblock ~2 ~29 ~-12 orange_concrete
setblock ~12 ~29 ~-2 orange_concrete
setblock ~12 ~29 ~2 orange_concrete
setblock ~-12 ~29 ~-2 orange_concrete
setblock ~-12 ~29 ~2 orange_concrete
setblock ~-1 ~30 ~11 orange_concrete
setblock ~1 ~30 ~11 orange_concrete
setblock ~-1 ~30 ~-11 orange_concrete
setblock ~1 ~30 ~-11 orange_concrete
setblock ~11 ~30 ~-1 orange_concrete
setblock ~11 ~30 ~1 orange_concrete
setblock ~-11 ~30 ~-1 orange_concrete
setblock ~-11 ~30 ~1 orange_concrete
setblock ~1 ~31 ~11 orange_concrete
setblock ~-1 ~31 ~11 orange_concrete
setblock ~1 ~31 ~-11 orange_concrete
setblock ~-1 ~31 ~-11 orange_concrete
setblock ~11 ~31 ~1 orange_concrete
setblock ~11 ~31 ~-1 orange_concrete
setblock ~-11 ~31 ~1 orange_concrete
setblock ~-11 ~31 ~-1 orange_concrete
setblock ~3 ~32 ~11 orange_concrete
setblock ~-3 ~32 ~11 orange_concrete
setblock ~3 ~32 ~-11 orange_concrete
setblock ~-3 ~32 ~-11 orange_concrete
setblock ~11 ~32 ~3 orange_concrete
setblock ~11 ~32 ~-3 orange_concrete
setblock ~-11 ~32 ~3 orange_concrete
setblock ~-11 ~32 ~-3 orange_concrete
setblock ~5 ~33 ~11 orange_concrete
setblock ~-5 ~33 ~11 orange_concrete
setblock ~5 ~33 ~-11 orange_concrete
setblock ~-5 ~33 ~-11 orange_concrete
setblock ~11 ~33 ~5 orange_concrete
setblock ~11 ~33 ~-5 orange_concrete
setblock ~-11 ~33 ~5 orange_concrete
setblock ~-11 ~33 ~-5 orange_concrete
setblock ~7 ~34 ~11 orange_concrete
setblock ~-7 ~34 ~11 orange_concrete
setblock ~7 ~34 ~-11 orange_concrete
setblock ~-7 ~34 ~-11 orange_concrete
setblock ~11 ~34 ~7 orange_concrete
setblock ~11 ~34 ~-7 orange_concrete
setblock ~-11 ~34 ~7 orange_concrete
setblock ~-11 ~34 ~-7 orange_concrete
setblock ~9 ~35 ~11 orange_concrete
setblock ~-9 ~35 ~11 orange_concrete
setblock ~9 ~35 ~-11 orange_concrete
setblock ~-9 ~35 ~-11 orange_concrete
setblock ~11 ~35 ~9 orange_concrete
setblock ~11 ~35 ~-9 orange_concrete
setblock ~-11 ~35 ~9 orange_concrete
setblock ~-11 ~35 ~-9 orange_concrete
setblock ~-9 ~37 ~11 white_concrete
setblock ~9 ~37 ~11 white_concrete
setblock ~-9 ~37 ~-11 white_concrete
setblock ~9 ~37 ~-11 white_concrete
setblock ~11 ~37 ~-9 white_concrete
setblock ~11 ~37 ~9 white_concrete
setblock ~-11 ~37 ~-9 white_concrete
setblock ~-11 ~37 ~9 white_concrete
setblock ~-7 ~38 ~11 white_concrete
setblock ~7 ~38 ~11 white_concrete
setblock ~-7 ~38 ~-11 white_concrete
setblock ~7 ~38 ~-11 white_concrete
setblock ~11 ~38 ~-7 white_concrete
setblock ~11 ~38 ~7 white_concrete
setblock ~-11 ~38 ~-7 white_concrete
setblock ~-11 ~38 ~7 white_concrete
setblock ~-6 ~39 ~11 white_concrete
setblock ~6 ~39 ~11 white_concrete
setblock ~-6 ~39 ~-11 white_concrete
setblock ~6 ~39 ~-11 white_concrete
setblock ~11 ~39 ~-6 white_concrete
setblock ~11 ~39 ~6 white_concrete
setblock ~-11 ~39 ~-6 white_concrete
setblock ~-11 ~39 ~6 white_concrete
setblock ~-4 ~40 ~11 white_concrete
setblock ~4 ~40 ~11 white_concrete
setblock ~-4 ~40 ~-11 white_concrete
setblock ~4 ~40 ~-11 white_concrete
setblock ~11 ~40 ~-4 white_concrete
setblock ~11 ~40 ~4 white_concrete
setblock ~-11 ~40 ~-4 white_concrete
setblock ~-11 ~40 ~4 white_concrete
setblock ~-2 ~41 ~11 white_concrete
setblock ~2 ~41 ~11 white_concrete
setblock ~-2 ~41 ~-11 white_concrete
setblock ~2 ~41 ~-11 white_concrete
setblock ~11 ~41 ~-2 white_concrete
setblock ~11 ~41 ~2 white_concrete
setblock ~-11 ~41 ~-2 white_concrete
setblock ~-11 ~41 ~2 white_concrete
setblock ~-1 ~42 ~10 white_concrete
setblock ~1 ~42 ~10 white_concrete
setblock ~-1 ~42 ~-10 white_concrete
setblock ~1 ~42 ~-10 white_concrete
setblock ~10 ~42 ~-1 white_concrete
setblock ~10 ~42 ~1 white_concrete
setblock ~-10 ~42 ~-1 white_concrete
setblock ~-10 ~42 ~1 white_concrete
setblock ~1 ~43 ~10 white_concrete
setblock ~-1 ~43 ~10 white_concrete
setblock ~1 ~43 ~-10 white_concrete
setblock ~-1 ~43 ~-10 white_concrete
setblock ~10 ~43 ~1 white_concrete
setblock ~10 ~43 ~-1 white_concrete
setblock ~-10 ~43 ~1 white_concrete
setblock ~-10 ~43 ~-1 white_concrete
setblock ~3 ~44 ~10 white_concrete
setblock ~-3 ~44 ~10 white_concrete
setblock ~3 ~44 ~-10 white_concrete
setblock ~-3 ~44 ~-10 white_concrete
setblock ~10 ~44 ~3 white_concrete
setblock ~10 ~44 ~-3 white_concrete
setblock ~-10 ~44 ~3 white_concrete
setblock ~-10 ~44 ~-3 white_concrete
setblock ~5 ~45 ~10 white_concrete
setblock ~-5 ~45 ~10 white_concrete
setblock ~5 ~45 ~-10 white_concrete
setblock ~-5 ~45 ~-10 white_concrete
setblock ~10 ~45 ~5 white_concrete
setblock ~10 ~45 ~-5 white_concrete
setblock ~-10 ~45 ~5 white_concrete
setblock ~-10 ~45 ~-5 white_concrete
setblock ~6 ~46 ~10 white_concrete
setblock ~-6 ~46 ~10 white_concrete
setblock ~6 ~46 ~-10 white_concrete
setblock ~-6 ~46 ~-10 white_concrete
setblock ~10 ~46 ~6 white_concrete
setblock ~10 ~46 ~-6 white_concrete
setblock ~-10 ~46 ~6 white_concrete
setblock ~-10 ~46 ~-6 white_concrete
setblock ~8 ~47 ~10 white_concrete
setblock ~-8 ~47 ~10 white_concrete
setblock ~8 ~47 ~-10 white_concrete
setblock ~-8 ~47 ~-10 white_concrete
setblock ~10 ~47 ~8 white_concrete
setblock ~10 ~47 ~-8 white_concrete
setblock ~-10 ~47 ~8 white_concrete
setblock ~-10 ~47 ~-8 white_concrete
setblock ~-8 ~49 ~10 orange_concrete
setblock ~8 ~49 ~10 orange_concrete
setblock ~-8 ~49 ~-10 orange_concrete
setblock ~8 ~49 ~-10 orange_concrete
setblock ~10 ~49 ~-8 orange_concrete
setblock ~10 ~49 ~8 orange_concrete
setblock ~-10 ~49 ~-8 orange_concrete
setblock ~-10 ~49 ~8 orange_concrete
setblock ~-7 ~50 ~10 orange_concrete
setblock ~7 ~50 ~10 orange_concrete
setblock ~-7 ~50 ~-10 orange_concrete
setblock ~7 ~50 ~-10 orange_concrete
setblock ~10 ~50 ~-7 orange_concrete
setblock ~10 ~50 ~7 orange_concrete
setblock ~-10 ~50 ~-7 orange_concrete
setblock ~-10 ~50 ~7 orange_concrete
setblock ~-5 ~51 ~10 orange_concrete
setblock ~5 ~51 ~10 orange_concrete
setblock ~-5 ~51 ~-10 orange_concrete
setblock ~5 ~51 ~-10 orange_concrete
setblock ~10 ~51 ~-5 orange_concrete
setblock ~10 ~51 ~5 orange_concrete
setblock ~-10 ~51 ~-5 orange_concrete
setblock ~-10 ~51 ~5 orange_concrete
setblock ~-4 ~52 ~10 orange_concrete
setblock ~4 ~52 ~10 orange_concrete
setblock ~-4 ~52 ~-10 orange_concrete
setblock ~4 ~52 ~-10 orange_concrete
setblock ~10 ~52 ~-4 orange_concrete
setblock ~10 ~52 ~4 orange_concrete
setblock ~-10 ~52 ~-4 orange_concrete
setblock ~-10 ~52 ~4 orange_concrete
setblock ~-2 ~53 ~9 orange_concrete
setblock ~2 ~53 ~9 orange_concrete
setblock ~-2 ~53 ~-9 orange_concrete
setblock ~2 ~53 ~-9 orange_concrete
setblock ~9 ~53 ~-2 orange_concrete
setblock ~9 ~53 ~2 orange_concrete
setblock ~-9 ~53 ~-2 orange_concrete
setblock ~-9 ~53 ~2 orange_concrete
setblock ~-1 ~54 ~9 orange_concrete
setblock ~1 ~54 ~9 orange_concrete
setblock ~-1 ~54 ~-9 orange_concrete
setblock ~1 ~54 ~-9 orange_concrete
setblock ~9 ~54 ~-1 orange_concrete
setblock ~9 ~54 ~1 orange_concrete
setblock ~-9 ~54 ~-1 orange_concrete
setblock ~-9 ~54 ~1 orange_concrete
setblock ~1 ~55 ~9 orange_concrete
setblock ~-1 ~55 ~9 orange_concrete
setblock ~1 ~55 ~-9 orange_concrete
setblock ~-1 ~55 ~-9 orange_concrete
setblock ~9 ~55 ~1 orange_concrete
setblock ~9 ~55 ~-1 orange_concrete
setblock ~-9 ~55 ~1 orange_concrete
setblock ~-9 ~55 ~-1 orange_concrete
setblock ~3 ~56 ~9 orange_concrete
setblock ~-3 ~56 ~9 orange_concrete
setblock ~3 ~56 ~-9 orange_concrete
setblock ~-3 ~56 ~-9 orange_concrete
setblock ~9 ~56 ~3 orange_concrete
setblock ~9 ~56 ~-3 orange_concrete
setblock ~-9 ~56 ~3 orange_concrete
setblock ~-9 ~56 ~-3 orange_concrete
setblock ~4 ~57 ~9 orange_concrete
setblock ~-4 ~57 ~9 orange_concrete
setblock ~4 ~57 ~-9 orange_concrete
setblock ~-4 ~57 ~-9 orange_concrete
setblock ~9 ~57 ~4 orange_concrete
setblock ~9 ~57 ~-4 orange_concrete
setblock ~-9 ~57 ~4 orange_concrete
setblock ~-9 ~57 ~-4 orange_concrete
setblock ~6 ~58 ~9 orange_concrete
setblock ~-6 ~58 ~9 orange_concrete
setblock ~6 ~58 ~-9 orange_concrete
setblock ~-6 ~58 ~-9 orange_concrete
setblock ~9 ~58 ~6 orange_concrete
setblock ~9 ~58 ~-6 orange_concrete
setblock ~-9 ~58 ~6 orange_concrete
setblock ~-9 ~58 ~-6 orange_concrete
setblock ~7 ~59 ~9 orange_concrete
setblock ~-7 ~59 ~9 orange_concrete
setblock ~7 ~59 ~-9 orange_concrete
setblock ~-7 ~59 ~-9 orange_concrete
setblock ~9 ~59 ~7 orange_concrete
setblock ~9 ~59 ~-7 orange_concrete
setblock ~-9 ~59 ~7 orange_concrete
setblock ~-9 ~59 ~-7 orange_concrete
setblock ~-7 ~61 ~9 white_concrete
setblock ~7 ~61 ~9 white_concrete
setblock ~-7 ~61 ~-9 white_concrete
setblock ~7 ~61 ~-9 white_concrete
setblock ~9 ~61 ~-7 white_concrete
setblock ~9 ~61 ~7 white_concrete
setblock ~-9 ~61 ~-7 white_concrete
setblock ~-9 ~61 ~7 white_concrete
setblock ~-6 ~62 ~9 white_concrete
setblock ~6 ~62 ~9 white_concrete
setblock ~-6 ~62 ~-9 white_concrete
setblock ~6 ~62 ~-9 white_concrete
setblock ~9 ~62 ~-6 white_concrete
setblock ~9 ~62 ~6 white_concrete
setblock ~-9 ~62 ~-6 white_concrete
setblock ~-9 ~62 ~6 white_concrete
setblock ~-5 ~63 ~9 white_concrete
setblock ~5 ~63 ~9 white_concrete
setblock ~-5 ~63 ~-9 white_concrete
setblock ~5 ~63 ~-9 white_concrete
setblock ~9 ~63 ~-5 white_concrete
setblock ~9 ~63 ~5 white_concrete
setblock ~-9 ~63 ~-5 white_concrete
setblock ~-9 ~63 ~5 white_concrete
setblock ~-3 ~64 ~8 white_concrete
setblock ~3 ~64 ~8 white_concrete
setblock ~-3 ~64 ~-8 white_concrete
setblock ~3 ~64 ~-8 white_concrete
setblock ~8 ~64 ~-3 white_concrete
setblock ~8 ~64 ~3 white_concrete
setblock ~-8 ~64 ~-3 white_concrete
setblock ~-8 ~64 ~3 white_concrete
setblock ~-2 ~65 ~8 white_concrete
setblock ~2 ~65 ~8 white_concrete
setblock ~-2 ~65 ~-8 white_concrete
setblock ~2 ~65 ~-8 white_concrete
setblock ~8 ~65 ~-2 white_concrete
setblock ~8 ~65 ~2 white_concrete
setblock ~-8 ~65 ~-2 white_concrete
setblock ~-8 ~65 ~2 white_concrete
setblock ~-1 ~66 ~8 white_concrete
setblock ~1 ~66 ~8 white_concrete
setblock ~-1 ~66 ~-8 white_concrete
setblock ~1 ~66 ~-8 white_concrete
setblock ~8 ~66 ~-1 white_concrete
setblock ~8 ~66 ~1 white_concrete
setblock ~-8 ~66 ~-1 white_concrete
setblock ~-8 ~66 ~1 white_concrete
setblock ~1 ~67 ~8 white_concrete
setblock ~-1 ~67 ~8 white_concrete
setblock ~1 ~67 ~-8 white_concrete
setblock ~-1 ~67 ~-8 white_concrete
setblock ~8 ~67 ~1 white_concrete
setblock ~8 ~67 ~-1 white_concrete
setblock ~-8 ~67 ~1 white_concrete
setblock ~-8 ~67 ~-1 white_concrete
setblock ~2 ~68 ~8 white_concrete
setblock ~-2 ~68 ~8 white_concrete
setblock ~2 ~68 ~-8 white_concrete
setblock ~-2 ~68 ~-8 white_concrete
setblock ~8 ~68 ~2 white_concrete
setblock ~8 ~68 ~-2 white_concrete
setblock ~-8 ~68 ~2 white_concrete
setblock ~-8 ~68 ~-2 white_concrete
setblock ~4 ~69 ~8 white_concrete
setblock ~-4 ~69 ~8 white_concrete
setblock ~4 ~69 ~-8 white_concrete
setblock ~-4 ~69 ~-8 white_concrete
setblock ~8 ~69 ~4 white_concrete
setblock ~8 ~69 ~-4 white_concrete
setblock ~-8 ~69 ~4 white_concrete
setblock ~-8 ~69 ~-4 white_concrete
setblock ~5 ~70 ~8 white_concrete
setblock ~-5 ~70 ~8 white_concrete
setblock ~5 ~70 ~-8 white_concrete
setblock ~-5 ~70 ~-8 white_concrete
setblock ~8 ~70 ~5 white_concrete
setblock ~8 ~70 ~-5 white_concrete
setblock ~-8 ~70 ~5 white_concrete
setblock ~-8 ~70 ~-5 white_concrete
setblock ~6 ~71 ~8 white_concrete
setblock ~-6 ~71 ~8 white_concrete
setblock ~6 ~71 ~-8 white_concrete
setblock ~-6 ~71 ~-8 white_concrete
setblock ~8 ~71 ~6 white_concrete
setblock ~8 ~71 ~-6 white_concrete
setblock ~-8 ~71 ~6 white_concrete
setblock ~-8 ~71 ~-6 white_concrete
setblock ~-6 ~73 ~8 orange_concrete
setblock ~6 ~73 ~8 orange_concrete
setblock ~-6 ~73 ~-8 orange_concrete
setblock ~6 ~73 ~-8 orange_concrete
setblock ~8 ~73 ~-6 orange_concrete
setblock ~8 ~73 ~6 orange_concrete
setblock ~-8 ~73 ~-6 orange_concrete
setblock ~-8 ~73 ~6 orange_concrete
setblock ~-5 ~74 ~7 orange_concrete
setblock ~5 ~74 ~7 orange_concrete
setblock ~-5 ~74 ~-7 orange_concrete
setblock ~5 ~74 ~-7 orange_concrete
setblock ~7 ~74 ~-5 orange_concrete
setblock ~7 ~74 ~5 orange_concrete
setblock ~-7 ~74 ~-5 orange_concrete
setblock ~-7 ~74 ~5 orange_concrete
setblock ~-4 ~75 ~7 orange_concrete
setblock ~4 ~75 ~7 orange_concrete
setblock ~-4 ~75 ~-7 orange_concrete
setblock ~4 ~75 ~-7 orange_concrete
setblock ~7 ~75 ~-4 orange_concrete
setblock ~7 ~75 ~4 orange_concrete
setblock ~-7 ~75 ~-4 orange_concrete
setblock ~-7 ~75 ~4 orange_concrete
setblock ~-3 ~76 ~7 orange_concrete
setblock ~3 ~76 ~7 orange_concrete
setblock ~-3 ~76 ~-7 orange_concrete
setblock ~3 ~76 ~-7 orange_concrete
setblock ~7 ~76 ~-3 orange_concrete
setblock ~7 ~76 ~3 orange_concrete
setblock ~-7 ~76 ~-3 orange_concrete
setblock ~-7 ~76 ~3 orange_concrete
setblock ~-2 ~77 ~7 orange_concrete
setblock ~2 ~77 ~7 orange_concrete
setblock ~-2 ~77 ~-7 orange_concrete
setblock ~2 ~77 ~-7 orange_concrete
setblock ~7 ~77 ~-2 orange_concrete
setblock ~7 ~77 ~2 orange_concrete
setblock ~-7 ~77 ~-2 orange_concrete
setblock ~-7 ~77 ~2 orange_concrete
setblock ~-1 ~78 ~7 orange_concrete
setblock ~1 ~78 ~7 orange_concrete
setblock ~-1 ~78 ~-7 orange_concrete
setblock ~1 ~78 ~-7 orange_concrete
setblock ~7 ~78 ~-1 orange_concrete
setblock ~7 ~78 ~1 orange_concrete
setblock ~-7 ~78 ~-1 orange_concrete
setblock ~-7 ~78 ~1 orange_concrete
setblock ~1 ~79 ~7 orange_concrete
setblock ~-1 ~79 ~7 orange_concrete
setblock ~1 ~79 ~-7 orange_concrete
setblock ~-1 ~79 ~-7 orange_concrete
setblock ~7 ~79 ~1 orange_concrete
setblock ~7 ~79 ~-1 orange_concrete
setblock ~-7 ~79 ~1 orange_concrete
setblock ~-7 ~79 ~-1 orange_concrete
setblock ~2 ~80 ~7 orange_concrete
setblock ~-2 ~80 ~7 orange_concrete
setblock ~2 ~80 ~-7 orange_concrete
setblock ~-2 ~80 ~-7 orange_concrete
setblock ~7 ~80 ~2 orange_concrete
setblock ~7 ~80 ~-2 orange_concrete
setblock ~-7 ~80 ~2 orange_concrete
setblock ~-7 ~80 ~-2 orange_concrete
setblock ~3 ~81 ~7 orange_concrete
setblock ~-3 ~81 ~7 orange_concrete
setblock ~3 ~81 ~-7 orange_concrete
setblock ~-3 ~81 ~-7 orange_concrete
setblock ~7 ~81 ~3 orange_concrete
setblock ~7 ~81 ~-3 orange_concrete
setblock ~-7 ~81 ~3 orange_concrete
setblock ~-7 ~81 ~-3 orange_concrete
setblock ~4 ~82 ~7 orange_concrete
setblock ~-4 ~82 ~7 orange_concrete
setblock ~4 ~82 ~-7 orange_concrete
setblock ~-4 ~82 ~-7 orange_concrete
setblock ~7 ~82 ~4 orange_concrete
setblock ~7 ~82 ~-4 orange_concrete
setblock ~-7 ~82 ~4 orange_concrete
setblock ~-7 ~82 ~-4 orange_concrete
setblock ~5 ~83 ~7 orange_concrete
setblock ~-5 ~83 ~7 orange_concrete
setblock ~5 ~83 ~-7 orange_concrete
setblock ~-5 ~83 ~-7 orange_concrete
setblock ~7 ~83 ~5 orange_concrete
setblock ~7 ~83 ~-5 orange_concrete
setblock ~-7 ~83 ~5 orange_concrete
setblock ~-7 ~83 ~-5 orange_concrete
setblock ~-5 ~85 ~6 white_concrete
setblock ~5 ~85 ~6 white_concrete
setblock ~-5 ~85 ~-6 white_concrete
setblock ~5 ~85 ~-6 white_concrete
setblock ~6 ~85 ~-5 white_concrete
setblock ~6 ~85 ~5 white_concrete
setblock ~-6 ~85 ~-5 white_concrete
setblock ~-6 ~85 ~5 white_concrete
setblock ~-4 ~86 ~6 white_concrete
setblock ~4 ~86 ~6 white_concrete
setblock ~-4 ~86 ~-6 white_concrete
setblock ~4 ~86 ~-6 white_concrete
setblock ~6 ~86 ~-4 white_concrete
setblock ~6 ~86 ~4 white_concrete
setblock ~-6 ~86 ~-4 white_concrete
setblock ~-6 ~86 ~4 white_concrete
setblock ~-4 ~87 ~6 white_concrete
setblock ~4 ~87 ~6 white_concrete
setblock ~-4 ~87 ~-6 white_concrete
setblock ~4 ~87 ~-6 white_concrete
setblock ~6 ~87 ~-4 white_concrete
setblock ~6 ~87 ~4 white_concrete
setblock ~-6 ~87 ~-4 white_concrete
setblock ~-6 ~87 ~4 white_concrete
setblock ~-3 ~88 ~6 white_concrete
setblock ~3 ~88 ~6 white_concrete
setblock ~-3 ~88 ~-6 white_concrete
setblock ~3 ~88 ~-6 white_concrete
setblock ~6 ~88 ~-3 white_concrete
setblock ~6 ~88 ~3 white_concrete
setblock ~-6 ~88 ~-3 white_concrete
setblock ~-6 ~88 ~3 white_concrete
setblock ~-2 ~89 ~6 white_concrete
setblock ~2 ~89 ~6 white_concrete
setblock ~-2 ~89 ~-6 white_concrete
setblock ~2 ~89 ~-6 white_concrete
setblock ~6 ~89 ~-2 white_concrete
setblock ~6 ~89 ~2 white_concrete
setblock ~-6 ~89 ~-2 white_concrete
setblock ~-6 ~89 ~2 white_concrete
setblock ~-1 ~90 ~6 white_concrete
setblock ~1 ~90 ~6 white_concrete
setblock ~-1 ~90 ~-6 white_concrete
setblock ~1 ~90 ~-6 white_concrete
setblock ~6 ~90 ~-1 white_concrete
setblock ~6 ~90 ~1 white_concrete
setblock ~-6 ~90 ~-1 white_concrete
setblock ~-6 ~90 ~1 white_concrete
setblock ~0 ~91 ~6 white_concrete
setblock ~0 ~91 ~6 white_concrete
setblock ~0 ~91 ~-6 white_concrete
setblock ~0 ~91 ~-6 white_concrete
setblock ~6 ~91 ~0 white_concrete
setblock ~6 ~91 ~0 white_concrete
setblock ~-6 ~91 ~0 white_concrete
setblock ~-6 ~91 ~0 white_concrete
setblock ~1 ~92 ~6 white_concrete
setblock ~-1 ~92 ~6 white_concrete
setblock ~1 ~92 ~-6 white_concrete
setblock ~-1 ~92 ~-6 white_concrete
setblock ~6 ~92 ~1 white_concrete
setblock ~6 ~92 ~-1 white_concrete
setblock ~-6 ~92 ~1 white_concrete
setblock ~-6 ~92 ~-1 white_concrete
setblock ~2 ~93 ~5 white_concrete
setblock ~-2 ~93 ~5 white_concrete
setblock ~2 ~93 ~-5 white_concrete
setblock ~-2 ~93 ~-5 white_concrete
setblock ~5 ~93 ~2 white_concrete
setblock ~5 ~93 ~-2 white_concrete
setblock ~-5 ~93 ~2 white_concrete
setblock ~-5 ~93 ~-2 white_concrete
setblock ~3 ~94 ~5 white_concrete
setblock ~-3 ~94 ~5 white_concrete
setblock ~3 ~94 ~-5 white_concrete
setblock ~-3 ~94 ~-5 white_concrete
setblock ~5 ~94 ~3 white_concrete
setblock ~5 ~94 ~-3 white_concrete
setblock ~-5 ~94 ~3 white_concrete
setblock ~-5 ~94 ~-3 white_concrete
setblock ~4 ~95 ~5 white_concrete
setblock ~-4 ~95 ~5 white_concrete
setblock ~4 ~95 ~-5 white_concrete
setblock ~-4 ~95 ~-5 white_concrete
setblock ~5 ~95 ~4 white_concrete
setblock ~5 ~95 ~-4 white_concrete
setblock ~-5 ~95 ~4 white_concrete
setblock ~-5 ~95 ~-4 white_concrete
setblock ~-4 ~97 ~5 orange_concrete
setblock ~4 ~97 ~5 orange_concrete
setblock ~-4 ~97 ~-5 orange_concrete
setblock ~4 ~97 ~-5 orange_concrete
setblock ~5 ~97 ~-4 orange_concrete
setblock ~5 ~97 ~4 orange_concrete
setblock ~-5 ~97 ~-4 orange_concrete
setblock ~-5 ~97 ~4 orange_concrete
setblock ~-4 ~98 ~5 orange_concrete
setblock ~4 ~98 ~5 orange_concrete
setblock ~-4 ~98 ~-5 orange_concrete
setblock ~4 ~98 ~-5 orange_concrete
setblock ~5 ~98 ~-4 orange_concrete
setblock ~5 ~98 ~4 orange_concrete
setblock ~-5 ~98 ~-4 orange_concrete
setblock ~-5 ~98 ~4 orange_concrete
setblock ~-3 ~99 ~5 orange_concrete
setblock ~3 ~99 ~5 orange_concrete
setblock ~-3 ~99 ~-5 orange_concrete
setblock ~3 ~99 ~-5 orange_concrete
setblock ~5 ~99 ~-3 orange_concrete
setblock ~5 ~99 ~3 orange_concrete
setblock ~-5 ~99 ~-3 orange_concrete
setblock ~-5 ~99 ~3 orange_concrete
setblock ~-2 ~100 ~5 orange_concrete
setblock ~2 ~100 ~5 orange_concrete
setblock ~-2 ~100 ~-5 orange_concrete
setblock ~2 ~100 ~-5 orange_concrete
setblock ~5 ~100 ~-2 orange_concrete
setblock ~5 ~100 ~2 orange_concrete
setblock ~-5 ~100 ~-2 orange_concrete
setblock ~-5 ~100 ~2 orange_concrete
setblock ~-1 ~101 ~5 orange_concrete
setblock ~1 ~101 ~5 orange_concrete
setblock ~-1 ~101 ~-5 orange_concrete
setblock ~1 ~101 ~-5 orange_concrete
setblock ~5 ~101 ~-1 orange_concrete
setblock ~5 ~101 ~1 orange_concrete
setblock ~-5 ~101 ~-1 orange_concrete
setblock ~-5 ~101 ~1 orange_concrete
setblock ~-1 ~102 ~4 orange_concrete
setblock ~1 ~102 ~4 orange_concrete
setblock ~-1 ~102 ~-4 orange_concrete
setblock ~1 ~102 ~-4 orange_concrete
setblock ~4 ~102 ~-1 orange_concrete
setblock ~4 ~102 ~1 orange_concrete
setblock ~-4 ~102 ~-1 orange_concrete
setblock ~-4 ~102 ~1 orange_concrete
setblock ~0 ~103 ~4 orange_concrete
setblock ~0 ~103 ~4 orange_concrete
setblock ~0 ~103 ~-4 orange_concrete
setblock ~0 ~103 ~-4 orange_concrete
setblock ~4 ~103 ~0 orange_concrete
setblock ~4 ~103 ~0 orange_concrete
setblock ~-4 ~103 ~0 orange_concrete
setblock ~-4 ~103 ~0 orange_concrete
setblock ~1 ~104 ~4 orange_concrete
setblock ~-1 ~104 ~4 orange_concrete
setblock ~1 ~104 ~-4 orange_concrete
setblock ~-1 ~104 ~-4 orange_concrete
setblock ~4 ~104 ~1 orange_concrete
setblock ~4 ~104 ~-1 orange_concrete
setblock ~-4 ~104 ~1 orange_concrete
setblock ~-4 ~104 ~-1 orange_concrete
setblock ~1 ~105 ~4 orange_concrete
setblock ~-1 ~105 ~4 orange_concrete
setblock ~1 ~105 ~-4 orange_concrete
setblock ~-1 ~105 ~-4 orange_concrete
setblock ~4 ~105 ~1 orange_concrete
setblock ~4 ~105 ~-1 orange_concrete
setblock ~-4 ~105 ~1 orange_concrete
setblock ~-4 ~105 ~-1 orange_concrete
setblock ~2 ~106 ~4 orange_concrete
setblock ~-2 ~106 ~4 orange_concrete
setblock ~2 ~106 ~-4 orange_concrete
setblock ~-2 ~106 ~-4 orange_concrete
setblock ~4 ~106 ~2 orange_concrete
setblock ~4 ~106 ~-2 orange_concrete
setblock ~-4 ~106 ~2 orange_concrete
setblock ~-4 ~106 ~-2 orange_concrete
setblock ~3 ~107 ~4 orange_concrete
setblock ~-3 ~107 ~4 orange_concrete
setblock ~3 ~107 ~-4 orange_concrete
setblock ~-3 ~107 ~-4 orange_concrete
setblock ~4 ~107 ~3 orange_concrete
setblock ~4 ~107 ~-3 orange_concrete
setblock ~-4 ~107 ~3 orange_concrete
setblock ~-4 ~107 ~-3 orange_concrete
setblock ~-3 ~109 ~4 white_concrete
setblock ~3 ~109 ~4 white_concrete
setblock ~-3 ~109 ~-4 white_concrete
setblock ~3 ~109 ~-4 white_concrete
setblock ~4 ~109 ~-3 white_concrete
setblock ~4 ~109 ~3 white_concrete
setblock ~-4 ~109 ~-3 white_concrete
setblock ~-4 ~109 ~3 white_concrete
setblock ~-3 ~110 ~3 white_concrete
setblock ~3 ~110 ~3 white_concrete
setblock ~-3 ~110 ~-3 white_concrete
setblock ~3 ~110 ~-3 white_concrete
setblock ~3 ~110 ~-3 white_concrete
setblock ~3 ~110 ~3 white_concrete
setblock ~-3 ~110 ~-3 white_concrete
setblock ~-3 ~110 ~3 white_concrete
setblock ~-2 ~111 ~3 white_concrete
setblock ~2 ~111 ~3 white_concrete
setblock ~-2 ~111 ~-3 white_concrete
setblock ~2 ~111 ~-3 white_concrete
setblock ~3 ~111 ~-2 white_concrete
setblock ~3 ~111 ~2 white_concrete
setblock ~-3 ~111 ~-2 white_concrete
setblock ~-3 ~111 ~2 white_concrete
setblock ~-2 ~112 ~3 white_concrete
setblock ~2 ~112 ~3 white_concrete
setblock ~-2 ~112 ~-3 white_concrete
setblock ~2 ~112 ~-3 white_concrete
setblock ~3 ~112 ~-2 white_concrete
setblock ~3 ~112 ~2 white_concrete
setblock ~-3 ~112 ~-2 white_concrete
setblock ~-3 ~112 ~2 white_concrete
setblock ~-1 ~113 ~3 white_concrete
setblock ~1 ~113 ~3 white_concrete
setblock ~-1 ~113 ~-3 white_concrete
setblock ~1 ~113 ~-3 white_concrete
setblock ~3 ~113 ~-1 white_concrete
setblock ~3 ~113 ~1 white_concrete
setblock ~-3 ~113 ~-1 white_concrete
setblock ~-3 ~113 ~1 white_concrete
setblock ~-1 ~114 ~3 white_concrete
setblock ~1 ~114 ~3 white_concrete
setblock ~-1 ~114 ~-3 white_concrete
setblock ~1 ~114 ~-3 white_concrete
setblock ~3 ~114 ~-1 white_concrete
setblock ~3 ~114 ~1 white_concrete
setblock ~-3 ~114 ~-1 white_concrete
setblock ~-3 ~114 ~1 white_concrete
setblock ~0 ~115 ~3 white_concrete
setblock ~0 ~115 ~3 white_concrete
setblock ~0 ~115 ~-3 white_concrete
setblock ~0 ~115 ~-3 white_concrete
setblock ~3 ~115 ~0 white_concrete
setblock ~3 ~115 ~0 white_concrete
setblock ~-3 ~115 ~0 white_concrete
setblock ~-3 ~115 ~0 white_concrete
setblock ~0 ~116 ~3 white_concrete
setblock ~0 ~116 ~3 white_concrete
setblock ~0 ~116 ~-3 white_concrete
setblock ~0 ~116 ~-3 white_concrete
setblock ~3 ~116 ~0 white_concrete
setblock ~3 ~116 ~0 white_concrete
setblock ~-3 ~116 ~0 white_concrete
setblock ~-3 ~116 ~0 white_concrete
setblock ~1 ~117 ~2 white_concrete
setblock ~-1 ~117 ~2 white_concrete
setblock ~1 ~117 ~-2 white_concrete
setblock ~-1 ~117 ~-2 white_concrete
setblock ~2 ~117 ~1 white_concrete
setblock ~2 ~117 ~-1 white_concrete
setblock ~-2 ~117 ~1 white_concrete
setblock ~-2 ~117 ~-1 white_concrete
setblock ~1 ~118 ~2 white_concrete
setblock ~-1 ~118 ~2 white_concrete
setblock ~1 ~118 ~-2 white_concrete
setblock ~-1 ~118 ~-2 white_concrete
setblock ~2 ~118 ~1 white_concrete
setblock ~2 ~118 ~-1 white_concrete
setblock ~-2 ~118 ~1 white_concrete
setblock ~-2 ~118 ~-1 white_concrete
setblock ~2 ~119 ~2 white_concrete
setblock ~-2 ~119 ~2 white_concrete
setblock ~2 ~119 ~-2 white_concrete
setblock ~-2 ~119 ~-2 white_concrete
setblock ~2 ~119 ~2 white_concrete
setblock ~2 ~119 ~-2 white_concrete
setblock ~-2 ~119 ~2 white_concrete
setblock ~-2 ~119 ~-2 white_concrete

# アンテナ
setblock ~0 ~130 ~0 orange_concrete
setblock ~0 ~131 ~0 orange_concrete
setblock ~0 ~132 ~0 orange_concrete
setblock ~0 ~133 ~0 orange_concrete
setblock ~0 ~134 ~0 orange_concrete
setblock ~0 ~135 ~0 orange_concrete
setblock ~0 ~136 ~0 orange_concrete
setblock ~0 ~137 ~0 orange_concrete
setblock ~0 ~138 ~0 orange_concrete
setblock ~0 ~139 ~0 orange_concrete
setblock ~0 ~140 ~0 orange_concrete
setblock ~0 ~141 ~0 orange_concrete
setblock ~0 ~142 ~0 orange_concrete
setblock ~0 ~143 ~0 orange_concrete
setblock ~0 ~144 ~0 orange_concrete
setblock ~0 ~145 ~0 orange_concrete
setblock ~0 ~146 ~0 orange_concrete
setblock ~0 ~147 ~0 orange_concrete
setblock ~0 ~148 ~0 orange_concrete
setblock ~0 ~149 ~0 orange_concrete
setblock ~0 ~149 ~0 sea_lantern
setblock ~0 ~150 ~0 lightning_rod

# ライトアップ
setblock ~14 ~0 ~14 glowstone
setblock ~14 ~0 ~-14 glowstone
setblock ~-14 ~0 ~14 glowstone
setblock ~-14 ~0 ~-14 glowstone
setblock ~13 ~8 ~13 glowstone
setblock ~13 ~8 ~-13 glowstone
setblock ~-13 ~8 ~13 glowstone
setblock ~-13 ~8 ~-13 glowstone
setblock ~13 ~16 ~13 glowstone
setblock ~13 ~16 ~-13 glowstone
setblock ~-13 ~16 ~13 glowstone
setblock ~-13 ~16 ~-13 glowstone
setblock ~12 ~24 ~12 glowstone
setblock ~12 ~24 ~-12 glowstone
setblock ~-12 ~24 ~12 glowstone
setblock ~-12 ~24 ~-12 glowstone
setblock ~11 ~32 ~11 glowstone
setblock ~11 ~32 ~-11 glowstone
setblock ~-11 ~32 ~11 glowstone
setblock ~-11 ~32 ~-11 glowstone
setblock ~11 ~40 ~11 glowstone
setblock ~11 ~40 ~-11 glowstone
setblock ~-11 ~40 ~11 glowstone
setblock ~-11 ~40 ~-11 glowstone
setblock ~10 ~48 ~10 glowstone
setblock ~10 ~48 ~-10 glowstone
setblock ~-10 ~48 ~10 glowstone
setblock ~-10 ~48 ~-10 glowstone
setblock ~9 ~56 ~9 glowstone
setblock ~9 ~56 ~-9 glowstone
setblock ~-9 ~56 ~9 glowstone
setblock ~-9 ~56 ~-9 glowstone
setblock ~8 ~64 ~8 glowstone
setblock ~8 ~64 ~-8 glowstone
setblock ~-8 ~64 ~8 glowstone
setblock ~-8 ~64 ~-8 glowstone
setblock ~8 ~72 ~8 glowstone
setblock ~8 ~72 ~-8 glowstone
setblock ~-8 ~72 ~8 glowstone
setblock ~-8 ~72 ~-8 glowstone
setblock ~7 ~80 ~7 glowstone
setblock ~7 ~80 ~-7 glowstone
setblock ~-7 ~80 ~7 glowstone
setblock ~-7 ~80 ~-7 glowstone
setblock ~6 ~88 ~6 glowstone
setblock ~6 ~88 ~-6 glowstone
setblock ~-6 ~88 ~6 glowstone
setblock ~-6 ~88 ~-6 glowstone
setblock ~5 ~96 ~5 glowstone
setblock ~5 ~96 ~-5 glowstone
setblock ~-5 ~96 ~5 glowstone
setblock ~-5 ~96 ~-5 glowstone
setblock ~4 ~104 ~4 glowstone
setblock ~4 ~104 ~-4 glowstone
setblock ~-4 ~104 ~4 glowstone
setblock ~-4 ~104 ~-4 glowstone

tellraw @a [{"text":"[東京タワー] ","color":"red","bold":true},{"text":"建設完了！高さ150ブロック","color":"gold"}]
playsound minecraft:ui.toast.challenge_complete master @s ~ ~ ~ 1 1